Workbook
Name _Corporativo_SPE: _tCorporativo[Corporativo_SPE]
Name _Corporativo_SPE: _tCorporativo[Corporativo_SPE]
Name _Corporativo_SPE: _tCorporativo[Corporativo_SPE]
Name _Corporativo_SPE: _tCorporativo[Corporativo_SPE]
Name _InvContratado: Tabela24[Investimento Contratado]
Name _InvContratado: Tabela24[Investimento Contratado]
Name _InvContratado: Tabela24[Investimento Contratado]
Name _InvContratado: Tabela24[Investimento Contratado]
Name _Investimento_Novo: Tabela22[Investimento Novo]
Name _Investimento_Novo: Tabela22[Investimento Novo]
Name _Investimento_Novo: Tabela22[Investimento Novo]
Name _Investimento_Novo: Tabela22[Investimento Novo]
Name _Segmento: Tabela19[Segmento]
Name _Segmento: Tabela19[Segmento]
Name _Segmento: Tabela19[Segmento]
Name _Segmento: Tabela19[Segmento]
Name _VP: _tVP[VP]
Name _VP: _tVP[VP]
Name _VP: _tVP[VP]
Name _VP: _tVP[VP]
Name Ambiental: _Config!$J$5
Name AmbientalAmbiental: _Config!$U$16:$U$18
Name Corporativo: _Config!$F$24:$F$27
Name Furnas: #REF!
Name Geração: _Config!$K$5:$K$8
Name GeraçãoAmpliação: _Config!$J$16
Name GeraçãoMelhoriaPequenoPorte: _Config!$P$16:$P$19
Name GeraçãoModernização: _Config!$T$16:$T$18
Name GeraçãoSegurançadeBarragem: _Config!$S$16
Name Infraestrutura: _Config!$L$5:$L$7
Name Infraestrutura_ajustada_26012025: #REF!
Name InfraestruturaBensImóveis: _Config!$W$16:$W$17
Name InfraestruturaBensMóveis: _Config!$V$16:$V$19
Name InfraestruturaTecnologiadaInformação: _Config!$X$16:$X$19
Name Reforços_E_Melhorias: _Config!$R$16:$R$20
Name SPE: _Config!$F$28:$F$42
Name Status: #REF!
Name Transmissão: _Config!$M$5:$M$10
Name TransmissãoAmpliação: _Config!$Q$16
Name TransmissãoInvestimentodeApoio: _Config!$K$16:$K$18
Name TransmissãoMelhoriaGrandePorte: _Config!$L$16:$L$18
Name TransmissãoMelhoriaPequenoPorte: _Config!$O$16:$O$19
Name TransmissãoReforçoGrandePorte: _Config!$M$16:$M$18
Name TransmissãoReforçoPequenoPorte: _Config!$N$16:$N$19
Name TRGP: _xlfn._xlws.FILTER(RMGDE[],RMGDE[Categoria do Investimento]="RGP","")
Name TRGP: _xlfn._xlws.FILTER([1]!RMGDE[#Data],[1]!RMGDE[Categoria do Investimento]="RGP","")
Name TRGP: _xlfn._xlws.FILTER(RMGDE[],RMGDE[Categoria do Investimento]="RGP","")
Name TRGP: _xlfn._xlws.FILTER(RMGDE[],RMGDE[Categoria do Investimento]="RGP","")
Name TRGP: _xlfn._xlws.FILTER(RMGDE[],RMGDE[Categoria do Investimento]="RGP","")

Sheet Modelo_aPreencher
B3: Instruções de preenchimento
B5: 1. Indicar nas células em amarelo da coluna D se a área utiliza ou não o campo na planilha de Capex
B6: 2. Campos em branco serão entendidos como não utilizados
B7: 3. Campos em azul já preenchidos pela EDE
B8: 4. Os campos seguem a mesma sequência da planilha original, em caso de dúvida o campo original está na guia "MODELO" deste arquivo
B11: Coluna | C11: Descrição do Campo | D11: Área utiliza Projeção? (Sim/Não)
B12: 1 | C12: Analise Estrategia | D12: Suporte EDE
B13: 2 | C13: Check | D13: Suporte EDE
B14: 3 | C14: Arquivo | D14: Suporte EDE
B15: 4 | C15: Origem | D15: Suporte EDE
B16: 5 | C16: VP | D16: Necessário
B17: 6 | C17: Responsável | D17: Necessário
B18: 7 | C18: Conferido | D18: Necessário
B19: 8 | C19: Id PDNG
B20: 9 | C20: N° PDNG
B21: 10 | C21: Empresa | D21: Necessário
B22: 11 | C22: Corporativo ou SPE | D22: Necessário
B23: 12 | C23: Segmento | D23: Necessário
B24: 13 | C24: Descrição da ação
C26: CATEGORIZAÇÃO DO INVESTIMENTO
B27: 14 | C27: Especificação PDNG
B28: 15 | C28: Código SAP | D28: Necessário quando existente
B29: 16 | C29: Instalação | D29: Necessário quando puder especificar
B30: 17 | C30: Investimento Novo | D30: Necessário
B31: 18 | C31: Número da ação ou Nome Projeto
B32: 19 | C32: Fonte de geração
B33: 20 | C33: Período e prazo de execução do projeto (Projetos de Geração)
B34: 21 | C34: Especificar receita
B35: 22 | C35: Data de início da operação comercial | D35: Necessário para novos investimentos
B36: 23 | C36: Fonte de recurso
B37: 24 | C37: MW (Projetos de Geração)
B38: 25 | C38: Investimento Contratado
B39: 26 | C39: Evidência
B40: 27 | C40: Status financeiro do investimento
B41: 28 | C41: Descrição detalhada do investimento (escopo)
B42: 29 | C42: Área responsável
B43: 30 | C43: Categorização CISE
B44: 31 | C44: Destinação investimento
C46: PROJEÇÃO
B47: 32 | C47: jan/24 | D47: Necessário
...

Sheet Atividades
B3: Id | C3: Descrição | D3: Status
B4: =ROW(Tabela3[[#This Row],[Id]])-ROW(Tabela3[[#Headers],[Id]]) -> 1 | C4: Solicitar às áreas a indicação de quais colunas utilizam para sanear a quantidade de informação necessária | D4: Em andamento Email 28/05, recebido até 05/06 VEE, COO, OORC, VID
B5: =ROW(Tabela3[[#This Row],[Id]])-ROW(Tabela3[[#Headers],[Id]]) -> 2 | C5: Acertar com Jairo planilhas acessórias para SAP no caso dos R&M de pp
B6: =ROW(Tabela3[[#This Row],[Id]])-ROW(Tabela3[[#Headers],[Id]]) -> 3 | C6: Para Transmissão, alinhar: COO: usava [Categorização CISE] + [Destinação do investimento] para R&M VEE: usava [Categorização CISE] + [Descrição detalhada do investimento (escopo)]
B7: =ROW(Tabela3[[#This Row],[Id]])-ROW(Tabela3[[#Headers],[Id]]) -> 4 | C7: Solução da planilha excel para recebimento e consolidação dos dados: A. A logica de consolidação continua e mesma? B. quais campos devem ter seu conteúdo limitado a uma lista. C. Atualizar guia de intruções de preenchimento D. Bloquear a inclusão de novas colunas?
B8: =ROW(Tabela3[[#This Row],[Id]])-ROW(Tabela3[[#Headers],[Id]]) -> 5 | C8: Estudar colunas que serão utilizadas para o PE 2025 e fazer proposição para as áreas do modelo final (se possível junto com as demais melhorias a seguir). 1. Proposta fechada com EDEP + EDEI + FRPCA 2. Proposta fechada com as áreas de projeção FRPP (Planejamento) + Regulação (receita de T) + VED SPEs 3. Proposta fechada com áreas finais
B9: =ROW(Tabela3[[#This Row],[Id]])-ROW(Tabela3[[#Headers],[Id]]) -> 6 | C9: Dashboard 1. Saída de dadose visualização 2. Comparação com ciclo anterior 3. Verificação de duplicidades
B10: =ROW(Tabela3[[#This Row],[Id]])-ROW(Tabela3[[#Headers],[Id]]) -> 7 | C10: Categorias CISE + Analise interna 1. Serão revistas? 2. A ideia de uma pré classificação interna será mantida?
B11: =ROW(Tabela3[[#This Row],[Id]])-ROW(Tabela3[[#Headers],[Id]]) -> 8 | C11: As projeções do PE 2024 serão limitadoras ou só comparadoras?
B12: =ROW(Tabela3[[#This Row],[Id]])-ROW(Tabela3[[#Headers],[Id]]) -> 9

Sheet Planilha1
A3: Rótulos de Linha | B3: Soma de 2026 | C3: Soma de 2026-2030
A4: CGT Eletrosul | B4: 14369772 | C4: 37223176
A5: Total Geral | B5: 14369772 | C5: 37223176

Sheet Grupo
A1: ID | B1: Gupo | C1: Projeto | D1: Usina | E1: 2026 | F1: 2027 | G1: 2028 | H1: 2029 | I1: 2030 | J1: 2029-2030 | K1: Gerencia | L1: Status da contratação | M1: Gestão do Projeto | N1: Acompanhamento
A2: COO.NO26.001 | B2: Grupo 4 | C2: Sistemas de Monitoramento para Transformadores | D2: Diversas UHE | E2: 0 | F2: 0 | G2: 7820000 | H2: 4692000 | I2: 0 | J2: 12512000 | K2: #N/A | L2: =VLOOKUP(A2,'Consolidado-Eletronorte'!BN:BO,2,FALSE) -> Contratado | M2: Não | N2: Não
A3: COO.NO26.007 | B3: Grupo 2 | C3: Unidade de filtração hidraulica do Regulador de velocidade com elemento absoluto e sistema monitoramento | D3: UHE BALBINA | E3: 0 | F3: 200000 | G3: 650000 | H3: 466666.67 | I3: 0 | J3: 1316666.7 | K3: AGMGNO | L3: =VLOOKUP(A3,'Consolidado-Eletronorte'!BN:BO,2,FALSE) -> Não iniciado
A4: COO.NO26.015 | B4: Grupo 4 | C4: Aquisição de um Gerador Diesel de Emergência | D4: UHE Balbina | E4: 4000000 | F4: 2000000 | G4: 0 | H4: 0 | I4: 0 | J4: 6000000 | K4: OOGBA.N | L4: =VLOOKUP(A4,'Consolidado-Eletronorte'!BN:BO,2,FALSE) -> Em negociação | M4: Cleomar | N4: Geovane
A5: COO.NO26.053 | B5: Grupo 5 | C5: Modernização RVT UHE Balbina | D5: UHE BALBINA | E5: 0 | F5: 20910319 | G5: 6233333.3 | H5: 0 | I5: 0 | J5: 27143652 | K5: OOPM.N | L5: =VLOOKUP(A5,'Consolidado-Eletronorte'!BN:BO,2,FALSE) -> Não iniciado | M5: Geovane | N5: Geovane
A6: COO.NO26.054 | B6: Grupo 4 | C6: SPCS balbina | D6: UHE BALBINA | E6: 0 | F6: 7200000 | G6: 0 | H6: 0 | I6: 0 | J6: 7200000 | K6: OOPM.N | L6: =VLOOKUP(A6,'Consolidado-Eletronorte'!BN:BO,2,FALSE) -> Não iniciado | M6: Geovane | N6: Geovane
A7: COO.NO26.055 | B7: Grupo 4 | C7: MODERNIZAÇÃO DO SISTEMA DE AR DE REGULAÇÃO UHE BALBINA | D7: UHE Balbina | E7: 0 | F7: 3000000 | G7: 3000000 | H7: 0 | I7: 0 | J7: 6000000 | K7: OOGBA.N | L7: =VLOOKUP(A7,'Consolidado-Eletronorte'!BN:BO,2,FALSE) -> Não iniciado | M7: Geovane | N7: Geovane
A8: COO.NO26.056 | B8: Grupo 3 | C8: MODERNIZAÇÃO DO SISTEMA RESFR. MANCAL COMBINADO UHE BALBINA | D8: UHE Balbina | E8: 0 | F8: 3000000 | G8: 500000 | H8: 0 | I8: 0 | J8: 3500000 | K8: OOGBA.N | L8: =VLOOKUP(A8,'Consolidado-Eletronorte'!BN:BO,2,FALSE) -> Não iniciado
A9: COO.NO26.061 | B9: Grupo 2 | C9: MODERNIZAÇÃO DO SIST INJEÇÃO DE ÓLEO MANCAL ESCORA UHE BALBINA | D9: UHE Balbina | E9: 0 | F9: 1200000 | G9: 300000 | H9: 0 | I9: 0 | J9: 1500000 | K9: OOGBA.N | L9: =VLOOKUP(A9,'Consolidado-Eletronorte'!BN:BO,2,FALSE) -> Não iniciado
A10: COO.NO26.062 | B10: Grupo 2 | C10: MODERNIZAÇÃO DO SISTEMA DE AR DE SERVIÇO UHE BALBINA | D10: UHE Balbina | E10: 0 | F10: 500000 | G10: 1000000 | H10: 0 | I10: 0 | J10: 1500000 | K10: OOGBA.N | L10: =VLOOKUP(A10,'Consolidado-Eletronorte'!BN:BO,2,FALSE) -> Não iniciado
A11: COO.NO26.063 | B11: Grupo 2 | C11: MODERNIZACAO DO SISTEMA DRENAGEM TAMPA DA TURBINA UHE BALBINA | D11: UHE Balbina | E11: 0 | F11: 600000 | G11: 400000 | H11: 0 | I11: 0 | J11: 1000000 | K11: OOGBA.N | L11: =VLOOKUP(A11,'Consolidado-Eletronorte'!BN:BO,2,FALSE) -> Não iniciado
A12: COO.NO26.067 | B12: Grupo 2 | C12: MODERNIZAÇÃO DO SISTEMA RESFR. MANCAL GERADOR UHE BALBINA | D12: UHE Balbina | E12: 0 | F12: 1000000 | G12: 0 | H12: 0 | I12: 0 | J12: 1000000 | K12: OOGBA.N | L12: =VLOOKUP(A12,'Consolidado-Eletronorte'!BN:BO,2,FALSE) -> Não iniciado
A13: COO.NO26.070 | B13: Grupo 2 | C13: Instalar comando e controle sistema de drenagem e esgotamento da UHE Balbina | D13: UHE BALBINA | E13: 0 | F13: 800000 | G13: 0 | H13: 0 | I13: 0 | J13: 800000 | K13: OOPM.N | L13: =VLOOKUP(A13,'Consolidado-Eletronorte'!BN:BO,2,FALSE) -> Não iniciado
A14: COO.NO26.074 | B14: Grupo 2 | C14: Implatação de rede aérea de alimentação na UHE Balbina | D14: UHE BALBINA | E14: 0 | F14: 600000 | G14: 0 | H14: 0 | I14: 0 | J14: 600000 | K14: OOPM.N | L14: =VLOOKUP(A14,'Consolidado-Eletronorte'!BN:BO,2,FALSE) -> Não iniciado
A15: COO.NO26.075 | B15: Grupo 1 | C15: Modernização Comportas Tomada D'agua UHE BALBINA | D15: UHE BALBINA | E15: 0 | F15: 250000 | G15: 250000 | H15: 0 | I15: 0 | J15: 500000 | K15: AGMGNO | L15: =VLOOKUP(A15,'Consolidado-Eletronorte'!BN:BO,2,FALSE) -> Não iniciado
A16: COO.NO26.077 | B16: Grupo 1 | C16: Modernização Comportas Vertedouro UHE BALBINA | D16: UHE BALBINA | E16: 0 | F16: 250000 | G16: 250000 | H16: 0 | I16: 0 | J16: 500000 | K16: AGMGNO | L16: =VLOOKUP(A16,'Consolidado-Eletronorte'!BN:BO,2,FALSE) -> Não iniciado
A17: COO.NO26.078 | B17: Grupo 1 | C17: Modernização do Serviço Auxiliar 125 VCC UHE Balbina | D17: UHE BALBINA | E17: 0 | F17: 250000 | G17: 250000 | H17: 0 | I17: 0 | J17: 500000 | K17: AGMGNO | L17: =VLOOKUP(A17,'Consolidado-Eletronorte'!BN:BO,2,FALSE) -> Não iniciado
A18: COO.NO26.080 | B18: Grupo 1 | C18: Modernização do Serviço Auxiliar 13,8 KVCA UHE Balbina | D18: UHE BALBINA | E18: 0 | F18: 250000 | G18: 250000 | H18: 0 | I18: 0 | J18: 500000 | K18: AGMGNO | L18: =VLOOKUP(A18,'Consolidado-Eletronorte'!BN:BO,2,FALSE) -> Não iniciado
A19: COO.NO26.081 | B19: Grupo 1 | C19: Modernização dos Centros de Carga Miscelânea 380 VCA UHE Balbina | D19: UHE BALBINA | E19: 0 | F19: 250000 | G19: 250000 | H19: 0 | I19: 0 | J19: 500000 | K19: AGMGNO | L19: =VLOOKUP(A19,'Consolidado-Eletronorte'!BN:BO,2,FALSE) -> Não iniciado
... A25: COO.NO26.041 | B25: Grupo 2 | C25: Sistema de Ventilação e exaustão das galerias da UHE Balbina. | D25: UHE Balbina | E25: 600000 | F25: 500000 | G25: 0 | H25: 0 | I25: 0 | J25: 1100000 | K25: OOGBA.N | L25: =VLOOKUP(A25,'Consolidado-Eletronorte'!BN:BO,2,FALSE) -> Em negociação
A26: COO.NO26.045 | B26: Grupo 1 | C26: Superação equipamentos vão da UG 03 da UHCN | D26: UHE Coaracy Nunes | E26: 200000 | F26: 0 | G26: 0 | H26: 0 | I26: 0 | J26: 200000 | K26: AGCGNO | L26: =VLOOKUP(A26,'Consolidado-Eletronorte'!BN:BO,2,FALSE) -> TR em elaboração | M26: Geovane | N26: Geovane
A27: COO.NO26.069 | B27: Grupo 3 | C27: Modernização Sistema de Proteção CNUGH-01 / CNUGH-02 | D27: UHE Coaracy Nunes | E27: 0 | F27: 1000000 | G27: 3000000 | H27: 500000 | I27: 0 | J27: 4500000 | K27: OOPM.N | L27: =VLOOKUP(A27,'Consolidado-Eletronorte'!BN:BO,2,FALSE) -> Não iniciado
A28: COO.NO26.071 | B28: Grupo 3 | C28: Modernização Ponte rolante da UHCN | D28: UHE Coaracy Nunes | E28: 0 | F28: 0 | G28: 1000000 | H28: 2000000 | I28: 1000000 | J28: 4000000 | K28: AGMGNO | L28: =VLOOKUP(A28,'Consolidado-Eletronorte'!BN:BO,2,FALSE) -> Não iniciado
A29: COO.NO26.084 | B29: Grupo 3 | C29: Modernização do Painel de comando dos GDE's | D29: UHE Coaracy Nunes | E29: 0 | F29: 1000000 | G29: 500000 | H29: 1000000 | I29: 0 | J29: 2500000 | K29: AGMGNO | L29: =VLOOKUP(A29,'Consolidado-Eletronorte'!BN:BO,2,FALSE) -> Não iniciado
A30: COO.NO26.104 | B30: Grupo 2 | C30: Aquisição de novo GDE de 400KVA | D30: UHE Coaracy Nunes | E30: 0 | F30: 600000 | G30: 300000 | H30: 0 | I30: 0 | J30: 900000 | K30: AGMGNO | L30: =VLOOKUP(A30,'Consolidado-Eletronorte'!BN:BO,2,FALSE) -> Não iniciado
A31: COO.NO26.118 | B31: Grupo 1 | C31: Modernização Sistema de Supervisão da UHCN | D31: UHE Coaracy Nunes | E31: 0 | F31: 250000 | G31: 250000 | H31: 0 | I31: 0 | J31: 500000 | K31: OOPM.N | L31: =VLOOKUP(A31,'Consolidado-Eletronorte'!BN:BO,2,FALSE) -> Não iniciado
A32: COO.NO26.029 | B32: Grupo 4 | C32: Sobressalentes Estrategicos UHCN | D32: UHE Coaracy Nunes | E32: 500000 | F32: 3200000 | G32: 1800000 | H32: 0 | I32: 0 | J32: 5500000 | K32: OOGCN.N | L32: =VLOOKUP(A32,'Consolidado-Eletronorte'!BN:BO,2,FALSE) -> Não iniciado | M32: Geovane | N32: Geovane
A33: COO.NO26.059 | B33: Grupo 4 | C33: Revitalização do Vertedouro da UHCN | D33: UHE Coaracy Nunes | E33: 0 | F33: 7500000 | G33: 7500000 | H33: 0 | I33: 0 | J33: 15000000 | K33: OOGCN.N | L33: =VLOOKUP(A33,'Consolidado-Eletronorte'!BN:BO,2,FALSE) -> Não iniciado | M33: Geovane | N33: Geovane
A34: COO.NO26.028 | B34: Grupo 3 | C34: Modernização da instrumentação da UHE Curuá-Una CUUGH01, 02 e 03 | D34: UHE Curuá Una | E34: 1000000 | F34: 2100000 | G34: 0 | H34: 0 | I34: 0 | J34: 3100000 | K34: AGMGNO | L34: =VLOOKUP(A34,'Consolidado-Eletronorte'!BN:BO,2,FALSE) -> Em negociação
A35: COO.NO26.043 | B35: Grupo 2 | C35: Modernização da subestação 138kV da UHE. | D35: UHE Curuá Una | E35: 577030 | F35: 900000 | G35: 0 | H35: 0 | I35: 0 | J35: 1477030 | K35: AGCGNO | L35: =VLOOKUP(A35,'Consolidado-Eletronorte'!BN:BO,2,FALSE) -> #N/A | M35: Geovane | N35: Geovane
A36: COO.NO26.017 | B36: Grupo 4 | C36: Substituição de transformador para a UHE Curuá-Una - UGH02 e reserva | D36: UHE Curuá Una | E36: 3000000 | F36: 1500000 | G36: 2000000 | H36: 0 | I36: 0 | J36: 6500000 | K36: AGMGNO | L36: =VLOOKUP(A36,'Consolidado-Eletronorte'!BN:BO,2,FALSE) -> Em negociação | M36: Marcio | N36: Marcio
A37: COO.NO26.018 | B37: Grupo 3 | C37: MODERNIZAÇÃO DO RTVX DAS UGHs 01,02 e 03 | D37: UHE Curuá Una | E37: 3000000 | F37: 0 | G37: 0 | H37: 0 | I37: 0 | J37: 3000000 | K37: OOPM.N | L37: =VLOOKUP(A37,'Consolidado-Eletronorte'!BN:BO,2,FALSE) -> Contratado
A38: COO.NO26.073 | B38: Grupo 3 | C38: Modernização das turbinas hidráulicas da UHE Curuá-Una UGH01.02 e 03 | D38: UHE Curuá Una | E38: 0 | F38: 3600000 | G38: 0 | H38: 0 | I38: 0 | J38: 3600000 | K38: #N/A | L38: =VLOOKUP(A38,'Consolidado-Eletronorte'!BN:BO,2,FALSE) -> Não iniciado
A39: COO.NO26.076 | B39: Grupo 3 | C39: Modernização do serviço auxiliar da usina, com substituição de cubículos e gavetas do circuito CA | D39: UHE Curuá Una | E39: 0 | F39: 2000000 | G39: 1500000 | H39: 0 | I39: 0 | J39: 3500000 | K39: AGMGNO | L39: =VLOOKUP(A39,'Consolidado-Eletronorte'!BN:BO,2,FALSE) -> Não iniciado
A40: COO.NO26.091 | B40: Grupo 2 | C40: Modernização do geradores elétricos da UHE Curuá-Uma-UGH01, 02 e 03 | D40: UHE Curuá Una | E40: 0 | F40: 1800000 | G40: 0 | H40: 0 | I40: 0 | J40: 1800000 | K40: #N/A | L40: =VLOOKUP(A40,'Consolidado-Eletronorte'!BN:BO,2,FALSE) -> Não iniciado
A41: COO.NO26.097 | B41: Grupo 2 | C41: Modernização da Ponte Rolante e Porticos da Casa de Força e Vertedouro | D41: UHE Curuá Una | E41: 0 | F41: 600000 | G41: 600000 | H41: 0 | I41: 0 | J41: 1200000 | K41: AGMGNO | L41: =VLOOKUP(A41,'Consolidado-Eletronorte'!BN:BO,2,FALSE) -> Não iniciado
A42: COO.NO26.107 | B42: Grupo 1 | C42: Modernização do disjuntor da LT CUTA-LI5-01 da UHE Curuá-Una | D42: UHE Curuá Una | E42: 0 | F42: 500000 | G42: 0 | H42: 0 | I42: 0 | J42: 500000 | K42: OOGCU.N | L42: =VLOOKUP(A42,'Consolidado-Eletronorte'!BN:BO,2,FALSE) -> Não iniciado
A43: COO.NO26.123 | B43: Grupo 1 | C43: Estação de tratamento de agua de serviço para minimizar a contaminação ferro bactéria | D43: UHE Curuá Una | E43: 0 | F43: 250000 | G43: 0 | H43: 0 | I43: 0 | J43: 250000 | K43: AGMGNO | L43: =VLOOKUP(A43,'Consolidado-Eletronorte'!BN:BO,2,FALSE) -> Não iniciado
A44: COO.NO26.079 | B44: Grupo 3 | C44: Instalação de câmeras interna e externa a casa de força | D44: UHE Curuá Una | E44: 0 | F44: 3000000 | G44: 0 | H44: 0 | I44: 0 | J44: 3000000 | K44: OOGCU.N | L44: =VLOOKUP(A44,'Consolidado-Eletronorte'!BN:BO,2,FALSE) -> Não iniciado
A45: COO.NO26.083 | B45: Grupo 3 | C45: Substituição de cadeias de isoladores da linha CUTA | D45: UHE Curuá Una | E45: 0 | F45: 3000000 | G45: 0 | H45: 0 | I45: 0 | J45: 3000000 | K45: ATMTLN | L45: =VLOOKUP(A45,'Consolidado-Eletronorte'!BN:BO,2,FALSE) -> Não iniciado
...

Sheet Consolidado-Eletronorte
C11: Empresa_G_COO_xxxx | AZ11: =AZ13-AZ12 -> -7.3000984e+09
B12: Investimentos PE 2025 | G12: PREENCHER | H12: =AND($H$13<>"",$H$14<>"") -> TRUE | J12: Dados Automáticos | L12: Informar o Departamento do responsável pela informação | M12: OBRIGATÓRIA: 1. Indicar o número do coletor PEP ou OI. 2. NÃO informar PEP que não esteja aberto no SAP. 3. TRANSMISSÃO: informação deve ser considerada uma linha para cada código SGPMR (nesse caso, repetir o PEP). | AZ12: 8172120000
B13: De 2026 à 2030 | G13: VP | H13: COO | I13: Arquivo | J13: {=MID(CELL("filename"),SEARCH("[",CELL("filename"))+1,SEARCH("]",CELL("filename"))-SEARCH("[",CELL("filename"))-1)} -> Capex Orcamentário_PE2026_2030_red_35_porcentoR3_consulta.xlsx | AI13: =SUBTOTAL(9,'Consolidado-Eletronorte'!$AI$19:$AI$147) -> 12228619 | AJ13: =SUBTOTAL(9,'Consolidado-Eletronorte'!$AJ$19:$AJ$147) -> 24351166 | AK13: =SUBTOTAL(9,'Consolidado-Eletronorte'!$AK$19:$AK$147) -> 10647998 | AL13: =SUBTOTAL(9,'Consolidado-Eletronorte'!$AL$19:$AL$147) -> 18239778 | AM13: =SUBTOTAL(9,'Consolidado-Eletronorte'!$AM$19:$AM$147) -> 47171527 | AN13: =SUBTOTAL(9,'Consolidado-Eletronorte'!$AN$19:$AN$147) -> 20725826 | AO13: =SUBTOTAL(9,'Consolidado-Eletronorte'!$AO$19:$AO$147) -> 18796443 | AP13: =SUBTOTAL(9,'Consolidado-Eletronorte'!$AP$19:$AP$147) -> 61703261 | AQ13: =SUBTOTAL(9,'Consolidado-Eletronorte'!$AQ$19:$AQ$147) -> 3981708.9 | AR13: =SUBTOTAL(9,'Consolidado-Eletronorte'!$AR$19:$AR$147) -> 28271723 | AS13: =SUBTOTAL(9,'Consolidado-Eletronorte'!$AS$19:$AS$147) -> 3585103.2 | AT13: =SUBTOTAL(9,'Consolidado-Eletronorte'!$AT$19:$AT$147) -> 15543707 | AU13: =SUBTOTAL(9,'Consolidado-Eletronorte'!$AU$19:$AU$147) -> 2.6524686e+08 | AV13: =SUBTOTAL(9,'Consolidado-Eletronorte'!$AV$19:$AV$147) -> 3.8509831e+08 | AW13: =SUBTOTAL(9,'Consolidado-Eletronorte'!$AW$19:$AW$147) -> 1.5070009e+08 | AX13: =SUBTOTAL(9,'Consolidado-Eletronorte'!$AX$19:$AX$147) -> 70476376 | AY13: =SUBTOTAL(9,'Consolidado-Eletronorte'!$AY$19:$AY$147) -> 500000 | AZ13: =SUBTOTAL(9,'Consolidado-Eletronorte'!$AZ$19:$AZ$147) -> 8.7202163e+08 | BA13: =SUBTOTAL(9,'Consolidado-Eletronorte'!$BA$19:$BA$147) -> 0 | BB13: =SUBTOTAL(9,'Consolidado-Eletronorte'!$BB$19:$BB$147) -> 0 | BC13: =SUBTOTAL(9,'Consolidado-Eletronorte'!$BC$19:$BC$147) -> 0 | BD13: =SUBTOTAL(9,'Consolidado-Eletronorte'!$BD$19:$BD$147) -> 0 | BE13: =SUBTOTAL(9,'Consolidado-Eletronorte'!$BE$19:$BE$147) -> 0 | BF13: =SUBTOTAL(9,'Consolidado-Eletronorte'!$BF$19:$BF$147) -> 8.7202163e+08 | BR13: =SUBTOTAL(9,'Consolidado-Eletronorte'!$BR$19:$BR$147) -> 3.3110227e+08 | BS13: Tubtotal 2026
G14: Responsável Preenchimento | H14: Lucas Martins | AI14: =SUM('Consolidado-Eletronorte'!$AI$19:$AI$147) -> 12228619 | AJ14: =SUM('Consolidado-Eletronorte'!$AJ$19:$AJ$147) -> 25312352 | AK14: =SUM('Consolidado-Eletronorte'!$AK$19:$AK$147) -> 11663498 | AL14: =SUM('Consolidado-Eletronorte'!$AL$19:$AL$147) -> 18239778 | AM14: =SUM('Consolidado-Eletronorte'!$AM$19:$AM$147) -> 48162027 | AN14: =SUM('Consolidado-Eletronorte'!$AN$19:$AN$147) -> 24291326 | AO14: =SUM('Consolidado-Eletronorte'!$AO$19:$AO$147) -> 18996443 | AP14: =SUM('Consolidado-Eletronorte'!$AP$19:$AP$147) -> 63440761 | AQ14: =SUM('Consolidado-Eletronorte'!$AQ$19:$AQ$147) -> 10497209 | AR14: =SUM('Consolidado-Eletronorte'!$AR$19:$AR$147) -> 36471723 | AS14: =SUM('Consolidado-Eletronorte'!$AS$19:$AS$147) -> 12634653 | AT14: =SUM('Consolidado-Eletronorte'!$AT$19:$AT$147) -> 20609207 | AU14: =SUM('Consolidado-Eletronorte'!$AU$19:$AU$147) -> 3.025476e+08 | AV14: =SUM('Consolidado-Eletronorte'!$AV$19:$AV$147) -> 5.7352292e+08 | AW14: =SUM('Consolidado-Eletronorte'!$AW$19:$AW$147) -> 2.5672696e+08 | AX14: =SUM('Consolidado-Eletronorte'!$AX$19:$AX$147) -> 1.1758504e+08 | AY14: =SUM('Consolidado-Eletronorte'!$AY$19:$AY$147) -> 1500000 | AZ14: =SUM('Consolidado-Eletronorte'!$AZ$19:$AZ$147) -> 1.2518825e+09 | BA14: =SUM('Consolidado-Eletronorte'!$BA$19:$BA$147) -> 0 | BB14: =SUM('Consolidado-Eletronorte'!$BB$19:$BB$147) -> 0 | BC14: =SUM('Consolidado-Eletronorte'!$BC$19:$BC$147) -> 0 | BD14: =SUM('Consolidado-Eletronorte'!$BD$19:$BD$147) -> 0 | BE14: =SUM('Consolidado-Eletronorte'!$BE$19:$BE$147) -> 0 | BF14: =SUM('Consolidado-Eletronorte'!$BF$19:$BF$147) -> 1.2518825e+09 | BR14: =SUM('Consolidado-Eletronorte'!$BR$19:$BR$147) -> 4.4070541e+08 | BS14: Total 2026
A15: =AND($H$12,'Consolidado-Eletronorte'!$B$19:$B$147) -> #REF! | B15: =_xlfn.CONCAT(D19) -> COO | BU15: 5472300 | BV15: =BU16*5 -> 4560250
J16: Linhas preenchidas = | K16: =COUNTIF('Consolidado-Eletronorte'!$B$19:$B$147,TRUE) -> 0 | BU16: =BU15/6 -> 912050
A17: NÃO PREENCHER - AUTOMÁTICO + EDEP + EDEI | H17: CATEGORIZAÇÃO DO INVESTIMENTO | M17: Dados SAP | N17: COMPLEMENTO | AI17: Investimentos R$ mil - nominal
A18: Analise Estrategia | B18: Check | C18: Arquivo | D18: VP | E18: Responsável | F18: Conferido | G18: Id PE | H18: Corporativo ou SPE | I18: Empresa | J18: Segmento | K18: Categoria Cise | L18: Subcategoria CISE | M18: Coletor de Custo | N18: Cód Projeto VED | O18: Cód SGPMR | P18: Número da LO | Q18: ID real | R18: Descrição do projeto | S18: ID real3 | T18: Categoria Cise2 | U18: Subcategoria CISE3 | V18: Coletor de Custo (Carga) | W18: PEP SIGEP | X18: PEP especifico | Y18: RC | Z18: Valor RC | AA18: Contrato | AB18: Valor Contrato | AC18: Pedido | AD18: Valor Pedido | AE18: Objeto | AF18: Contratada | AG18: Especificação | AH18: Local da Instalação | AI18: jan/26 | AJ18: fev/26 | AK18: mar/26 | AL18: abr/26 | AM18: mai/26 | AN18: jun/26 | AO18: jul/26 | AP18: ago/26 | AQ18: set/26 | AR18: out/26 | AS18: nov/26 | AT18: dez/26 | AU18: 2026 | AV18: 2027 | AW18: 2028 | AX18: 2029 | AY18: 2030 | AZ18: 2026-2030 | BA18: 2031 | BB18: 2032 | BC18: 2033 | BD18: 2034 | BE18: 2035 | BF18: 2026-2035 | BG18: sequencial | BH18: ID real2 | BI18: GRUPO | BJ18: Órgão Responsável | BK18: PE de Origem | BL18: ID de demanda candidata | BM18: ID Financeiro | BN18: ID real22 | BO18: Status Contratação | BP18: De_Para | BQ18: Status CISE | BR18: Valor original 2026 | BS18: Observações | BT18: ID real222 | BU18: Líder | BV18: Descrição do Projeto2
A19: 378 | B19: {=AND(ISTEXT('Consolidado-Eletronorte'!#REF!),SUM('Consolidado-Eletronorte'!#REF!)>0)} -> #REF! | C19: =$J$13 -> Capex Orcamentário_PE2026_2030_red_35_porcentoR3_consulta.xlsx | D19: =$H$13 -> COO | E19: =$H$14 -> Lucas Martins | F19: =_xlfn.CONCAT(Tabela10[[#This Row],[VP]],Tabela10[[#This Row],[Analise Estrategia]]) -> COO378 | G19: =_xlfn.CONCAT('Consolidado-Eletronorte'!#REF!,"_",ROW('Consolidado-Eletronorte'!#REF!)-ROW('Consolidado-Eletronorte'!$G$18)) -> #REF! | H19: Corporativo | I19: Eletronorte | J19: Geração | K19: Modernização | L19: Modernização | M19: NGHI.0066 | P19: 13592/2022 | Q19: COO.NO26.005 | R19: Modernização SPCS+ UHE Tucuruí | S19: COO.NO26.005 | T19: Modernização | U19: Modernização | V19: NGHI.0066 | W19: NGHI.0066 | AC19: 4500080379 | AD19: 9.0067892e+08 | AE19: SPCS + | AF19: VOITH HYDRO | AG19: Modernização SPCS, TR, RV, Servomotores, Distribuidor, Instrumentação e Auxiliareas CC e CA da UHE Tucuruí | AH19: UHE Tucuruí | AI19: 11888567 | AJ19: 20886114 | AK19: 6922894.6 | AL19: 1909305.8 | AM19: 35832721 | AN19: 15091387 | AO19: 16898138 | AP19: 22249746 | AQ19: 993648.17 | AR19: 11791477 | AS19: 2500000 | AT19: 2500000 | AU19: =SUM(Tabela10[[#This Row],[jan/26]:[dez/26]]) -> 1.49464e+08 | AV19: 1.8640498e+08 | AW19: 1.3832863e+08 | AX19: 69976376 | AY19: 500000 | AZ19: =SUM(Tabela10[[#This Row],[2026]:[2030]]) -> 5.4467398e+08 | BA19: 0 | BB19: 0 | BC19: 0 | BD19: 0 | BE19: 0 | BF19: =SUM(Tabela10[[#This Row],[2026-2030]:[2035]]) -> 5.4467398e+08 | BG19: {=_xlfn.SEQUENCE(COUNTA(Tabela10[Empresa]),1,1)} -> #VALUE! | BH19: COO.NO26.005 | BI19: =VLOOKUP(Tabela10[[#This Row],[ID real2]],[2]CONSOLIDADA!$AU:$AZ,6,FALSE) -> #N/A | BJ19: AGVA | BK19: 2024 | BL19: ENOR.00500.313 | BM19: COO0613 | BN19: COO.NO26.005 | BO19: Contratado | BP19: (PE) Requisitado e Contratado e com ID Financeira | BQ19: Contratado | BR19: 1.7128036e+08 | BS19: Curva reduzida em 83% | BT19: COO.NO26.005 | BU19: Murilo Mascarenhas Menezes | BV19: =Tabela10[[#This Row],[Descrição do projeto]] -> Modernização SPCS+ UHE Tucuruí
E20: =$H$14 -> Lucas Martins | G20: =_xlfn.CONCAT('Consolidado-Eletronorte'!$D20,"_",ROW('Consolidado-Eletronorte'!$G20)-ROW('Consolidado-Eletronorte'!$G$18)) -> _2 | Q20: COO.NO26.005 | R20: Modernização SPCS+ UHE Tucuruí | S20: COO.NO26.005 | T20: Modernização | U20: Modernização | V20: NGHI.0066 | W20: NGHI.0066 | AC20: 4500083678 | AD20: 6623940.5 | AE20: Suporte técnico a projetos de modernização e reforços da geração. | AF20: ENERGIA CONSULT ENGENHARIA CONSULTE | AU20: =SUM(Tabela10[[#This Row],[jan/26]:[dez/26]]) -> 0 | AZ20: =SUM(Tabela10[[#This Row],[2026]:[2030]]) -> 0 | BF20: =SUM(Tabela10[[#This Row],[2026-2030]:[2035]]) -> 0 | BG20: {=_xlfn.SEQUENCE(COUNTA(Tabela10[Empresa]),1,1)} -> #VALUE! | BH20: COO.NO26.005 | BI20: =VLOOKUP(Tabela10[[#This Row],[ID real2]],[2]CONSOLIDADA!$AU:$AZ,6,FALSE) -> #N/A | BJ20: AGVA | BN20: COO.NO26.005 | BT20: COO.NO26.005 | BU20: Murilo Mascarenhas Menezes | BV20: =Tabela10[[#This Row],[Descrição do projeto]] -> Modernização SPCS+ UHE Tucuruí
B21: {=AND(ISTEXT('Consolidado-Eletronorte'!$H21:$M21),SUM('Consolidado-Eletronorte'!$AI21:$BF21)>0)} -> FALSE | C21: =$J$13 -> Capex Orcamentário_PE2026_2030_red_35_porcentoR3_consulta.xlsx | D21: =$H$13 -> COO | E21: =$H$14 -> Lucas Martins | G21: =_xlfn.CONCAT('Consolidado-Eletronorte'!$D21,"_",ROW('Consolidado-Eletronorte'!$G21)-ROW('Consolidado-Eletronorte'!$G$18)) -> COO_3 | Q21: COO.NO26.005 | R21: Modernização SPCS+ UHE Tucuruí | S21: COO.NO26.005 | T21: Modernização | U21: Modernização | V21: NGHI.0066 | W21: NGHI.0066 | AA21: 4600002316 | AB21: 4906000.6 | AC21: 4500092563 | AD21: 4906000.6 | AE21: CABO ELÉTRICO 0,75KV 2X2, | AF21: ALPHA MARKTEC MATERIAIS ELETRICOS L | AU21: =SUM(Tabela10[[#This Row],[jan/26]:[dez/26]]) -> 0 | AZ21: =SUM(Tabela10[[#This Row],[2026]:[2030]]) -> 0 | BF21: =SUM(Tabela10[[#This Row],[2026-2030]:[2035]]) -> 0 | BG21: {=_xlfn.SEQUENCE(COUNTA(Tabela10[Empresa]),1,1)} -> #VALUE! | BH21: COO.NO26.005 | BI21: =VLOOKUP(Tabela10[[#This Row],[ID real2]],[2]CONSOLIDADA!$AU:$AZ,6,FALSE) -> #N/A | BJ21: AGVA | BN21: COO.NO26.005 | BT21: COO.NO26.005 | BU21: Murilo Mascarenhas Menezes | BV21: =Tabela10[[#This Row],[Descrição do projeto]] -> Modernização SPCS+ UHE Tucuruí
B22: {=AND(ISTEXT('Consolidado-Eletronorte'!$H22:$M22),SUM('Consolidado-Eletronorte'!$AI22:$BF22)>0)} -> FALSE | C22: =$J$13 -> Capex Orcamentário_PE2026_2030_red_35_porcentoR3_consulta.xlsx | D22: =$H$13 -> COO | E22: =$H$14 -> Lucas Martins | G22: =_xlfn.CONCAT('Consolidado-Eletronorte'!$D22,"_",ROW('Consolidado-Eletronorte'!$G22)-ROW('Consolidado-Eletronorte'!$G$18)) -> COO_4 | Q22: COO.NO26.005 | R22: Modernização SPCS+ UHE Tucuruí | S22: COO.NO26.005 | AC22: 4500083678 | AD22: 6623940.5 | AE22: SUP.TECNICO SPCS | AF22: ENERGIA CONSULT ENGENHARIA CONSULTE | AU22: =SUM(Tabela10[[#This Row],[jan/26]:[dez/26]]) -> 0 | AZ22: =SUM(Tabela10[[#This Row],[2026]:[2030]]) -> 0 | BF22: =SUM(Tabela10[[#This Row],[2026-2030]:[2035]]) -> 0 | BG22: {=_xlfn.SEQUENCE(COUNTA(Tabela10[Empresa]),1,1)} -> #VALUE! | BI22: =VLOOKUP(Tabela10[[#This Row],[ID real2]],[2]CONSOLIDADA!$AU:$AZ,6,FALSE) -> #N/A | BV22: =Tabela10[[#This Row],[Descrição do projeto]] -> Modernização SPCS+ UHE Tucuruí
A23: 373 | B23: {=AND(ISTEXT('Consolidado-Eletronorte'!#REF!),SUM('Consolidado-Eletronorte'!#REF!)>0)} -> #REF! | C23: =$J$13 -> Capex Orcamentário_PE2026_2030_red_35_porcentoR3_consulta.xlsx | D23: =$H$13 -> COO | E23: =$H$14 -> Lucas Martins | F23: =_xlfn.CONCAT(Tabela10[[#This Row],[VP]],Tabela10[[#This Row],[Analise Estrategia]]) -> COO373 | G23: =_xlfn.CONCAT('Consolidado-Eletronorte'!#REF!,"_",ROW('Consolidado-Eletronorte'!#REF!)-ROW('Consolidado-Eletronorte'!$G$18)) -> #REF! | H23: Corporativo | I23: Eletronorte | J23: Geração | K23: Modernização | L23: Modernização | M23: NGHI.0099 | P23: 13592/2022 | Q23: COO.NO26.008 | R23: Substituição Transformador 550kV UHE Tucuruí (5 trafo) | S23: COO.NO26.008 | T23: Modernização | U23: Modernização | V23: NGHI.0099 | W23: NGHI.0099 | Y23: 3400004035 | Z23: 226000000 | AA23: 4600002745 | AB23: 1.7527984e+08 | AC23: 4500093709 | AD23: 1.7527984e+08 | AE23: TRANSFORMADOR FORÇA | AF23: SIEMENS ENERGY BRASIL LTDA | AG23: Substituição devido superação da corrente de curto circuito | AH23: UHE Tucuruí | AI23: 0 | AL23: 0 | AM23: 0 | AO23: 0 | AP23: 19838464 | AT23: 10903655 | AU23: =SUM(Tabela10[[#This Row],[jan/26]:[dez/26]]) -> 30742119 | AV23: 1.6569211e+08 | AX23: 0 | AY23: 0 | AZ23: =SUM(Tabela10[[#This Row],[2026]:[2030]]) -> 1.9643423e+08 | BA23: 0 | BB23: 0 | BC23: 0 | BD23: 0 | BE23: 0 | BF23: =SUM(Tabela10[[#This Row],[2026-2030]:[2035]]) -> 1.9643423e+08 | BG23: {=_xlfn.SEQUENCE(COUNTA(Tabela10[Empresa]),1,1)} -> #VALUE! | BH23: COO.NO26.008 | BI23: =VLOOKUP(Tabela10[[#This Row],[ID real2]],[2]CONSOLIDADA!$AU:$AZ,6,FALSE) -> #N/A | BJ23: AGVA | BK23: 2024 | BL23: ENOR.00304 | BM23: COO0601 | BN23: COO.NO26.008 | BO23: Contratado | BP23: (PE) Requisitado e Contratado e com ID Financeira | BQ23: Contratado | BR23: 71760000 | BS23: Ajustado conforme contrato | BT23: COO.NO26.008 | BU23: Denis De Oliveira Neto | BV23: =Tabela10[[#This Row],[Descrição do projeto]] -> Substituição Transformador 550kV UHE Tucuruí (5 trafo)
B24: {=AND(ISTEXT('Consolidado-Eletronorte'!$H24:$M24),SUM('Consolidado-Eletronorte'!$AI24:$BF24)>0)} -> FALSE | C24: =$J$13 -> Capex Orcamentário_PE2026_2030_red_35_porcentoR3_consulta.xlsx | D24: =$H$13 -> COO | E24: =$H$14 -> Lucas Martins | G24: =_xlfn.CONCAT('Consolidado-Eletronorte'!$D24,"_",ROW('Consolidado-Eletronorte'!$G24)-ROW('Consolidado-Eletronorte'!$G$18)) -> COO_6 | Q24: COO.NO26.008 | R24: Substituição Transformador 550kV UHE Tucuruí (5 trafo) | S24: COO.NO26.008 | AC24: 4500083678 | AD24: 6623940.5 | AE24: SUP.TECNICO Trafos TUC | AF24: ENERGIA CONSULT ENGENHARIA CONSULTE | AU24: =SUM(Tabela10[[#This Row],[jan/26]:[dez/26]]) -> 0 | AZ24: =SUM(Tabela10[[#This Row],[2026]:[2030]]) -> 0 | BF24: =SUM(Tabela10[[#This Row],[2026-2030]:[2035]]) -> 0 | BG24: {=_xlfn.SEQUENCE(COUNTA(Tabela10[Empresa]),1,1)} -> #VALUE! | BI24: =VLOOKUP(Tabela10[[#This Row],[ID real2]],[2]CONSOLIDADA!$AU:$AZ,6,FALSE) -> #N/A | BV24: =Tabela10[[#This Row],[Descrição do projeto]] -> Substituição Transformador 550kV UHE Tucuruí (5 trafo)
A25: 372 | B25: {=AND(ISTEXT('Consolidado-Eletronorte'!#REF!),SUM('Consolidado-Eletronorte'!#REF!)>0)} -> #REF! | C25: =$J$13 -> Capex Orcamentário_PE2026_2030_red_35_porcentoR3_consulta.xlsx | D25: =$H$13 -> COO | E25: =$H$14 -> Lucas Martins | F25: =_xlfn.CONCAT(Tabela10[[#This Row],[VP]],Tabela10[[#This Row],[Analise Estrategia]]) -> COO372 | G25: =_xlfn.CONCAT('Consolidado-Eletronorte'!#REF!,"_",ROW('Consolidado-Eletronorte'!#REF!)-ROW('Consolidado-Eletronorte'!$G$18)) -> #REF! | H25: Corporativo | I25: Eletronorte | J25: Geração | K25: Modernização | L25: Modernização | M25: NGHI.0086 | P25: 13592/2022 | Q25: COO.NO26.006 | R25: Substituição GIS UHE Tucuruí | S25: COO.NO26.006 | T25: Modernização | U25: Modernização | V25: NGHI.0086 | W25: NGHI.0086 | AC25: 4500080069 | AD25: 97552545 | AE25: Substituição de 4 módulos da subestação blindada SF6 550 kV da CF1. | AF25: HITACHI ENERGY BRASIL LTDA | AG25: Substituição devido superação da corrente de curto circuito | AH25: UHE Tucuruí | AI25: 173385.49 | AJ25: 173385.49 | AK25: 173385.49 | AL25: 9038806 | AM25: 7332139.2 | AN25: 173385.49 | AO25: 281638.65 | AP25: 12423385 | AQ25: 676343.05 | AR25: 7463578.8 | AS25: 173385.49 | AT25: 173385.49 | AU25: =SUM(Tabela10[[#This Row],[jan/26]:[dez/26]]) -> 38256204 | AV25: 10144019 | AW25: 221463.61 | AX25: 0 | AY25: 0 | AZ25: =SUM(Tabela10[[#This Row],[2026]:[2030]]) -> 48621687 | BA25: 0 | BB25: 0 | BC25: 0 | BD25: 0 | BE25: 0 | BF25: =SUM(Tabela10[[#This Row],[2026-2030]:[2035]]) -> 48621687 | BG25: {=_xlfn.SEQUENCE(COUNTA(Tabela10[Empresa]),1,1)} -> #VALUE! | BH25: COO.NO26.006 | BI25: =VLOOKUP(Tabela10[[#This Row],[ID real2]],[2]CONSOLIDADA!$AU:$AZ,6,FALSE) -> #N/A | BJ25: AGVA | BK25: 2024 | BL25: ENOR.00303 | BM25: COO0596 | BN25: COO.NO26.006 | BO25: Contratado | BP25: (PE) Requisitado e Contratado e com ID Financeira | BQ25: Contratado | BR25: 33164958 | BS25: Não alterado | BT25: COO.NO26.006 | BU25: Daniel Branquinho Ferreira | BV25: =Tabela10[[#This Row],[Descrição do projeto]] -> Substituição GIS UHE Tucuruí
B26: {=AND(ISTEXT('Consolidado-Eletronorte'!$H26:$M26),SUM('Consolidado-Eletronorte'!$AI26:$BF26)>0)} -> FALSE | C26: =$J$13 -> Capex Orcamentário_PE2026_2030_red_35_porcentoR3_consulta.xlsx | D26: =$H$13 -> COO | E26: =$H$14 -> Lucas Martins | G26: =_xlfn.CONCAT('Consolidado-Eletronorte'!$D26,"_",ROW('Consolidado-Eletronorte'!$G26)-ROW('Consolidado-Eletronorte'!$G$18)) -> COO_8 | Q26: COO.NO26.006 | R26: Substituição GIS UHE Tucuruí | S26: COO.NO26.006 | AC26: 4500083678 | AD26: 6623940.5 | AE26: SUP.TECNICO TUC.GIS | AF26: ENERGIA CONSULT ENGENHARIA CONSULTE | AU26: =SUM(Tabela10[[#This Row],[jan/26]:[dez/26]]) -> 0 | AZ26: =SUM(Tabela10[[#This Row],[2026]:[2030]]) -> 0 | BF26: =SUM(Tabela10[[#This Row],[2026-2030]:[2035]]) -> 0 | BG26: {=_xlfn.SEQUENCE(COUNTA(Tabela10[Empresa]),1,1)} -> #VALUE! | BI26: =VLOOKUP(Tabela10[[#This Row],[ID real2]],[2]CONSOLIDADA!$AU:$AZ,6,FALSE) -> #N/A | BV26: =Tabela10[[#This Row],[Descrição do projeto]] -> Substituição GIS UHE Tucuruí
B27: {=AND(ISTEXT('Consolidado-Eletronorte'!$H27:$M27),SUM('Consolidado-Eletronorte'!$AI27:$BF27)>0)} -> FALSE | C27: =$J$13 -> Capex Orcamentário_PE2026_2030_red_35_porcentoR3_consulta.xlsx | D27: =$H$13 -> COO | E27: =$H$14 -> Lucas Martins | G27: =_xlfn.CONCAT('Consolidado-Eletronorte'!$D27,"_",ROW('Consolidado-Eletronorte'!$G27)-ROW('Consolidado-Eletronorte'!$G$18)) -> COO_9 | Q27: COO.NO26.006 | R27: Substituição GIS UHE Tucuruí | S27: COO.NO26.006 | X27: NGHI.0086.01.00001.004 | AC27: 4500044911 | AD27: 309000 | AE27: Recebimento e armazenamento de material | AF27: A. A. Moura | AU27: =SUM(Tabela10[[#This Row],[jan/26]:[dez/26]]) -> 0 | AZ27: =SUM(Tabela10[[#This Row],[2026]:[2030]]) -> 0 | BF27: =SUM(Tabela10[[#This Row],[2026-2030]:[2035]]) -> 0 | BG27: {=_xlfn.SEQUENCE(COUNTA(Tabela10[Empresa]),1,1)} -> #VALUE! | BI27: =VLOOKUP(Tabela10[[#This Row],[ID real2]],[2]CONSOLIDADA!$AU:$AZ,6,FALSE) -> #N/A | BV27: =Tabela10[[#This Row],[Descrição do projeto]] -> Substituição GIS UHE Tucuruí
A28: 379 | B28: {=AND(ISTEXT('Consolidado-Eletronorte'!#REF!),SUM('Consolidado-Eletronorte'!#REF!)>0)} -> #REF! | C28: =$J$13 -> Capex Orcamentário_PE2026_2030_red_35_porcentoR3_consulta.xlsx | D28: =$H$13 -> COO | E28: =$H$14 -> Lucas Martins | F28: =_xlfn.CONCAT(Tabela10[[#This Row],[VP]],Tabela10[[#This Row],[Analise Estrategia]]) -> COO379 | G28: =_xlfn.CONCAT('Consolidado-Eletronorte'!#REF!,"_",ROW('Consolidado-Eletronorte'!#REF!)-ROW('Consolidado-Eletronorte'!$G$18)) -> #REF! | H28: Corporativo | I28: Eletronorte | J28: Geração | K28: Modernização | L28: Modernização | M28: NGHI.0147 | P28: 157189 | Q28: COO.NO26.014 | R28: Modernização RVT UHE Samuel | S28: COO.NO26.014 | T28: Modernização | U28: Modernização | V28: NGHI.0147 | W28: NGHI.0147 | Y28: 3700008198 | Z28: 27910319 | AG28: Substituição dos comandos eletrônicos, de potencia e hidráulico dos reguladores de velocidade e tensão da UHE Samuel | AH28: UHE Samuel | AI28: 0 | AK28: 0 | AL28: 0 | AM28: 0 | AO28: 0 | AP28: 0 | AQ28: 0 | AR28: 2000000 | AS28: 2000000 | AT28: 0 | AU28: =SUM(Tabela10[[#This Row],[jan/26]:[dez/26]]) -> 4000000 | AV28: 23500000 | AW28: 0 | AX28: 0 | AY28: 0 | AZ28: =SUM(Tabela10[[#This Row],[2026]:[2030]]) -> 27500000 | BA28: 0 | BB28: 0 | BC28: 0 | BD28: 0 | BE28: 0 | BF28: =SUM(Tabela10[[#This Row],[2026-2030]:[2035]]) -> 27500000 | BG28: {=_xlfn.SEQUENCE(COUNTA(Tabela10[Empresa]),1,1)} -> #VALUE! | BH28: COO.NO26.014 | BI28: =VLOOKUP(Tabela10[[#This Row],[ID real2]],[2]CONSOLIDADA!$AU:$AZ,6,FALSE) -> #N/A | BJ28: OOPM.N | BK28: 2025 | BL28: ENOR.00501.011 | BM28: COO0708 | BN28: COO.NO26.014 | BO28: Em negociação | BP28: (PE) Requisitado e com ID Financeira | BQ28: Em Contratação | BR28: 13955160 | BS28: RD 2026 a 2028 | BT28: COO.NO26.014 | BU28: Klenio Dias Timoteo | BV28: =Tabela10[[#This Row],[Descrição do projeto]] -> Modernização RVT UHE Samuel
A29: 265 | B29: {=AND(ISTEXT('Consolidado-Eletronorte'!#REF!),SUM('Consolidado-Eletronorte'!#REF!)>0)} -> #REF! | C29: =$J$13 -> Capex Orcamentário_PE2026_2030_red_35_porcentoR3_consulta.xlsx | D29: =$H$13 -> COO | E29: =$H$14 -> Lucas Martins | F29: =_xlfn.CONCAT(Tabela10[[#This Row],[VP]],Tabela10[[#This Row],[Analise Estrategia]]) -> COO265 | G29: =_xlfn.CONCAT('Consolidado-Eletronorte'!#REF!,"_",ROW('Consolidado-Eletronorte'!#REF!)-ROW('Consolidado-Eletronorte'!$G$18)) -> #REF! | H29: Corporativo | I29: Eletronorte | J29: Geração | K29: Modernização | L29: Modernização | M29: NGHI.0143 | P29: 13592/2022 | Q29: COO.NO26.052 | R29: Substituição das capas isolantes dos geradores da casa de força 2 da UHE Tucuruí | S29: COO.NO26.052 | T29: Modernização | U29: Modernização | V29: NGHI.0143 | W29: NGHI.0143 | Y29: 3400004379 | Z29: 16274073 | AA29: 4600003254 | AB29: 14290398 | AE29: Substituição das capas do enrolamento do gerador | AF29: INSIGHT ENERGIA SERVICOS | AG29: Serviço de alteração das capas isolantes dos geradores da casa de força 2 | AH29: UHE Tucuruí | AI29: 0 | AJ29: 0 | AK29: 0 | AL29: 0 | AM29: 0 | AN29: 0 | AO29: 0 | AP29: 0 | AQ29: 0 | AS29: 0 | AU29: =SUM(Tabela10[[#This Row],[jan/26]:[dez/26]]) -> 0 | AV29: 16000000 | AW29: 16000000 | AX29: 16000000 | AY29: 0 | AZ29: =SUM(Tabela10[[#This Row],[2026]:[2030]]) -> 48000000 | BA29: 0 | BB29: 0 | BC29: 0 | BD29: 0 | BE29: 0 | BF29: =SUM(Tabela10[[#This Row],[2026-2030]:[2035]]) -> 48000000 | BG29: {=_xlfn.SEQUENCE(COUNTA(Tabela10[Empresa]),1,1)} -> #VALUE! | BH29: COO.NO26.052 | BI29: =VLOOKUP(Tabela10[[#This Row],[ID real2]],[2]CONSOLIDADA!$AU:$AZ,6,FALSE) -> #N/A | BJ29: OOGTE.N | BK29: 2025 | BL29: ENOR.00003.001 | BM29: COO0719 | BN29: COO.NO26.052 | BO29: Em negociação | BP29: Nova Demanda | BQ29: Em Contratação | BR29: 12833768 | BS29: RD 2027 a 2029 | BT29: COO.NO26.052 | BU29: Albert Ferraz Botelho Da Silva | BV29: =Tabela10[[#This Row],[Descrição do projeto]] -> Substituição das capas isolantes dos geradores da casa de força 2 da UHE Tucuruí
A30: 356 | B30: {=AND(ISTEXT('Consolidado-Eletronorte'!#REF!),SUM('Consolidado-Eletronorte'!#REF!)>0)} -> #REF! | C30: =$J$13 -> Capex Orcamentário_PE2026_2030_red_35_porcentoR3_consulta.xlsx | D30: =$H$13 -> COO | E30: =$H$14 -> Lucas Martins | F30: =_xlfn.CONCAT(Tabela10[[#This Row],[VP]],Tabela10[[#This Row],[Analise Estrategia]]) -> COO356 | G30: =_xlfn.CONCAT('Consolidado-Eletronorte'!#REF!,"_",ROW('Consolidado-Eletronorte'!#REF!)-ROW('Consolidado-Eletronorte'!$G$18)) -> #REF! | H30: Corporativo | I30: Eletronorte | J30: Geração | K30: Modernização | L30: Modernização | M30: NGHI.0143 | P30: 13592/2022 | Q30: COO.NO26.058 | R30: Aquisição de 2 jogos de SotpLogs | S30: COO.NO26.058 | T30: Modernização | U30: Modernização | V30: NGHI.0143 | W30: NGHI.0143 | Y30: Não emitido | AG30: Fornecimento de dois jogos de SptoLogs, um para a CF I e outro para a CF 2. | AH30: UHE Tucuruí | AI30: 0 | AJ30: 0 | AK30: 0 | AL30: 0 | AM30: 0 | AN30: 0 | AO30: 0 | AP30: 0 | AQ30: 0 | AS30: 0 | AU30: =SUM(Tabela10[[#This Row],[jan/26]:[dez/26]]) -> 0 | AV30: 2000000 | AW30: 9500000 | AX30: 10000000 | AY30: 0 | AZ30: =SUM(Tabela10[[#This Row],[2026]:[2030]]) -> 21500000 | BA30: 0 | BB30: 0 | BC30: 0 | BD30: 0 | BE30: 0 | BF30: =SUM(Tabela10[[#This Row],[2026-2030]:[2035]]) -> 21500000 | BG30: {=_xlfn.SEQUENCE(COUNTA(Tabela10[Empresa]),1,1)} -> #VALUE! | BH30: COO.NO26.058 | BI30: =VLOOKUP(Tabela10[[#This Row],[ID real2]],[2]CONSOLIDADA!$AU:$AZ,6,FALSE) -> #N/A | BJ30: #N/A | BK30: 2025 | BL30: ENOR.00027 | BM30: COO0628 | BN30: COO.NO26.058 | BO30: Não iniciado | BP30: (PE) Não Requisitado e com ID Financeira | BQ30: RC não emitida | BR30: 2000000 | BS30: Avaliar projeto, pois não houve responsavel pelo projeto. Passar para o Fred | BT30: COO.NO26.058 | BU30: #N/A | BV30: =Tabela10[[#This Row],[Descrição do projeto]] -> Aquisição de 2 jogos de SotpLogs
A31: 362 | B31: {=AND(ISTEXT('Consolidado-Eletronorte'!#REF!),SUM('Consolidado-Eletronorte'!#REF!)>0)} -> #REF! | C31: =$J$13 -> Capex Orcamentário_PE2026_2030_red_35_porcentoR3_consulta.xlsx | D31: =$H$13 -> COO | E31: =$H$14 -> Lucas Martins | F31: =_xlfn.CONCAT(Tabela10[[#This Row],[VP]],Tabela10[[#This Row],[Analise Estrategia]]) -> COO362 | G31: =_xlfn.CONCAT('Consolidado-Eletronorte'!#REF!,"_",ROW('Consolidado-Eletronorte'!#REF!)-ROW('Consolidado-Eletronorte'!$G$18)) -> #REF! | H31: Corporativo | I31: Eletronorte | J31: Geração | K31: Modernização | L31: Modernização | M31: NGHI.0143 | P31: 13592/2022 | Q31: COO.NO26.011 | R31: Recuperação de cavitação e trincas nas UGHs da CF1 e CF2 | S31: COO.NO26.011 | T31: Modernização | U31: Modernização | V31: NGHI.0143 | W31: NGHI.0143 | AA31: 4600001776 | AB31: 15210891 | AE31: Cavitação | AF31: INSIGHT ENERGIA SERVICOS | AG31: Contratação de empresa especializada para manutenção e reforço operacional sistema de turbina recuperação de cavitação/trincas | AH31: UHE Tucuruí | AI31: 0 | AJ31: 0 | AK31: 0 | AL31: 0 | AM31: 0 | AN31: 0 | AO31: 0 | AP31: 0 | AQ31: 2000000 | AR31: 0 | AS31: 2000000 | AT31: 2000000 | AU31: =SUM(Tabela10[[#This Row],[jan/26]:[dez/26]]) -> 6000000 | AV31: 7000000 | AW31: 4000000 | AX31: 4000000 | AY31: 0 | AZ31: =SUM(Tabela10[[#This Row],[2026]:[2030]]) -> 21000000 | BA31: 0 | BB31: 0 | BC31: 0 | BD31: 0 | BE31: 0 | BF31: =SUM(Tabela10[[#This Row],[2026-2030]:[2035]]) -> 21000000 | BG31: {=_xlfn.SEQUENCE(COUNTA(Tabela10[Empresa]),1,1)} -> #VALUE! | BH31: COO.NO26.011 | BI31: =VLOOKUP(Tabela10[[#This Row],[ID real2]],[2]CONSOLIDADA!$AU:$AZ,6,FALSE) -> #N/A | BJ31: OOGTM.N | BK31: 2025 | BL31: ENOR.00124 | BM31: COO0685 | BN31: COO.NO26.011 | BO31: Contratado | BP31: (PE) Não Requisitado e com ID Financeira | BQ31: Contratado | BR31: 6000000 | BS31: Não alterado | BT31: COO.NO26.011 | BU31: Gilton Carlos De Andrade Furtado | BV31: =Tabela10[[#This Row],[Descrição do projeto]] -> Recuperação de cavitação e trincas nas UGHs da CF1 e CF2
A32: 370 | B32: {=AND(ISTEXT('Consolidado-Eletronorte'!#REF!),SUM('Consolidado-Eletronorte'!#REF!)>0)} -> #REF! | C32: =$J$13 -> Capex Orcamentário_PE2026_2030_red_35_porcentoR3_consulta.xlsx | D32: =$H$13 -> COO | E32: =$H$14 -> Lucas Martins | F32: =_xlfn.CONCAT(Tabela10[[#This Row],[VP]],Tabela10[[#This Row],[Analise Estrategia]]) -> COO370 | G32: =_xlfn.CONCAT('Consolidado-Eletronorte'!#REF!,"_",ROW('Consolidado-Eletronorte'!#REF!)-ROW('Consolidado-Eletronorte'!$G$18)) -> #REF! | H32: Corporativo | I32: Eletronorte | J32: Geração | K32: Modernização | L32: Modernização | M32: NGHI.0141 | P32: 13592/2022 | Q32: COO.NO26.021 | R32: Modernização Pórtico UHE Tucuruí | S32: COO.NO26.021 | T32: Modernização | U32: Modernização | V32: NGHI.0141 | W32: NGHI.0141 | Y32: 3400006178 | AG32: Modernização dos pórticos de Jusante e montante da UHE Tucuruí | AH32: UHE Tucuruí | AI32: 0 | AJ32: 0 | AL32: 0 | AM32: 0 | AN32: 0 | AP32: 0 | AQ32: 0 | AR32: 0 | AS32: 2000000 | AU32: =SUM(Tabela10[[#This Row],[jan/26]:[dez/26]]) -> 2000000 | AV32: 7400000 | AW32: 4000000 | AX32: 5000000 | AY32: 0 | AZ32: =SUM(Tabela10[[#This Row],[2026]:[2030]]) -> 18400000 | BA32: 0 | BB32: 0 | BC32: 0 | BD32: 0 | BE32: 0 | BF32: =SUM(Tabela10[[#This Row],[2026-2030]:[2035]]) -> 18400000 | BG32: {=_xlfn.SEQUENCE(COUNTA(Tabela10[Empresa]),1,1)} -> #VALUE! | BH32: COO.NO26.021 | BI32: =VLOOKUP(Tabela10[[#This Row],[ID real2]],[2]CONSOLIDADA!$AU:$AZ,6,FALSE) -> #N/A | BJ32: AGMGNO | BK32: 2025 | BL32: ENOR.00301.001 | BM32: COO0559 | BN32: COO.NO26.021 | BO32: RC aprovada | BP32: (PE) Requisitado e com ID Financeira | BQ32: Em Contratação | BR32: 7000000 | BS32: RD 2026 a 2029 | BT32: COO.NO26.021 | BU32: Frederico Rodolfo Parente Doerner | BV32: =Tabela10[[#This Row],[Descrição do projeto]] -> Modernização Pórtico UHE Tucuruí
A33: 380 | B33: {=AND(ISTEXT('Consolidado-Eletronorte'!#REF!),SUM('Consolidado-Eletronorte'!#REF!)>0)} -> #REF! | C33: =$J$13 -> Capex Orcamentário_PE2026_2030_red_35_porcentoR3_consulta.xlsx | D33: =$H$13 -> COO | E33: =$H$14 -> Lucas Martins | F33: =_xlfn.CONCAT(Tabela10[[#This Row],[VP]],Tabela10[[#This Row],[Analise Estrategia]]) -> COO380 | G33: =_xlfn.CONCAT('Consolidado-Eletronorte'!#REF!,"_",ROW('Consolidado-Eletronorte'!#REF!)-ROW('Consolidado-Eletronorte'!$G$18)) -> #REF! | H33: Corporativo | I33: Eletronorte | J33: Geração | K33: Modernização | L33: Modernização | M33: NGHI.0099 | P33: 13592/2022 | Q33: COO.NO26.012 | R33: Modernização de 02 Transformadores elevadores de 69kV (UGHs 24 e 25) da UHE Tucuruí | S33: COO.NO26.012 | T33: Modernização | U33: Modernização | V33: NGHI.0099 | W33: NGHI.0099 | Y33: 3400004381 | Z33: 12868088 | AG33: Aquisição de 2 (dois) transformadores elevadores trifásicos 69/13,8 kV – 28,75 MVA para casa de força I | AH33: UHE Tucuruí | AI33: 0 | AJ33: 0 | AL33: 0 | AM33: 0 | AN33: 1500000 | AO33: 0 | AP33: 0 | AQ33: 0 | AR33: 3500000 | AT33: 0 | AU33: =SUM(Tabela10[[#This Row],[jan/26]:[dez/26]]) -> 5000000 | AV33: 6750000 | AW33: 5000000 | AX33: 0 | AY33: 0 | AZ33: =SUM(Tabela10[[#This Row],[2026]:[2030]]) -> 16750000 | BA33: 0 | BB33: 0 | BC33: 0 | BD33: 0 | BE33: 0 | BF33: =SUM(Tabela10[[#This Row],[2026-2030]:[2035]]) -> 16750000 | BG33: {=_xlfn.SEQUENCE(COUNTA(Tabela10[Empresa]),1,1)} -> #VALUE! | BH33: COO.NO26.012 | BI33: =VLOOKUP(Tabela10[[#This Row],[ID real2]],[2]CONSOLIDADA!$AU:$AZ,6,FALSE) -> #N/A | BJ33: AGMGNO | BK33: 2025 | BL33: ENOR.00102 | BM33: COO0615 | BN33: COO.NO26.012 | BO33: Em negociação | BP33: Nova Demanda | BQ33: Em Contratação | BR33: 10000000 | BS33: RD 2026 a 2028 | BT33: COO.NO26.012 | BU33: Frederico Rodolfo Parente Doerner | BV33: =Tabela10[[#This Row],[Descrição do projeto]] -> Modernização de 02 Transformadores elevadores de 69kV (UGHs 24 e 25) da UHE Tucuruí
A34: 365 | B34: {=AND(ISTEXT('Consolidado-Eletronorte'!#REF!),SUM('Consolidado-Eletronorte'!#REF!)>0)} -> #REF! | C34: =$J$13 -> Capex Orcamentário_PE2026_2030_red_35_porcentoR3_consulta.xlsx | D34: =$H$13 -> COO | E34: =$H$14 -> Lucas Martins | F34: =_xlfn.CONCAT(Tabela10[[#This Row],[VP]],Tabela10[[#This Row],[Analise Estrategia]]) -> COO365 | G34: =_xlfn.CONCAT('Consolidado-Eletronorte'!#REF!,"_",ROW('Consolidado-Eletronorte'!#REF!)-ROW('Consolidado-Eletronorte'!$G$18)) -> #REF! | H34: Corporativo | I34: Eletronorte | J34: Geração | K34: Modernização | L34: Modernização | M34: NGHI.0143 | P34: 023/87-17 | Q34: COO.NO26.015 | R34: Aquisição de um Gerador Diesel de Emergência | S34: COO.NO26.015 | T34: Modernização | U34: Modernização | V34: NGHI.0143 | W34: NGHI.0143 | X34: NGHI.0143.10.00001.001 | Y34: 3400006809 | Z34: 8500000 | AG34: Implantação de Grupo Gerador cabinado | AH34: UHE Balbina | AI34: 0 | AJ34: 0 | AK34: 0 | AL34: 0 | AM34: 0 | AN34: 0 | AO34: 0 | AP34: 0 | AQ34: 2000000 | AR34: 0 | AS34: 0 | AT34: 2000000 | AU34: =SUM(Tabela10[[#This Row],[jan/26]:[dez/26]]) -> 4000000 | AV34: 2000000 | AW34: 0 | AX34: 0 | AY34: 0 | AZ34: =SUM(Tabela10[[#This Row],[2026]:[2030]]) -> 6000000 | BA34: 0 | BB34: 0 | BC34: 0 | BD34: 0 | BE34: 0 | BF34: =SUM(Tabela10[[#This Row],[2026-2030]:[2035]]) -> 6000000 | BG34: {=_xlfn.SEQUENCE(COUNTA(Tabela10[Empresa]),1,1)} -> #VALUE! | BH34: COO.NO26.015 | BI34: =VLOOKUP(Tabela10[[#This Row],[ID real2]],[2]CONSOLIDADA!$AU:$AZ,6,FALSE) -> #N/A | BJ34: OOGBA.N | BK34: 2026 | BL34: ENOR.00129.001 | BM34: 0 | BN34: COO.NO26.015 | BO34: Em negociação | BP34: Nova Demanda | BQ34: Em Contratação | BR34: 6000000 | BS34: RD 2026 a 2027 | BT34: COO.NO26.015 | BU34: Milton Pereira Menezes | BV34: =Tabela10[[#This Row],[Descrição do projeto]] -> Aquisição de um Gerador Diesel de Emergência
A35: 382 | B35: {=AND(ISTEXT('Consolidado-Eletronorte'!#REF!),SUM('Consolidado-Eletronorte'!#REF!)>0)} -> #REF! | C35: =$J$13 -> Capex Orcamentário_PE2026_2030_red_35_porcentoR3_consulta.xlsx | D35: =$H$13 -> COO | E35: =$H$14 -> Lucas Martins | F35: =_xlfn.CONCAT(Tabela10[[#This Row],[VP]],Tabela10[[#This Row],[Analise Estrategia]]) -> COO382 | G35: =_xlfn.CONCAT('Consolidado-Eletronorte'!#REF!,"_",ROW('Consolidado-Eletronorte'!#REF!)-ROW('Consolidado-Eletronorte'!$G$18)) -> #REF! | H35: Corporativo | I35: Eletronorte | J35: Geração | K35: Modernização | L35: Modernização | M35: NGHI.0099 | P35: 13592/2022 | Q35: COO.NO26.016 | R35: Revitalização de transformador para a UHE Tucurui | S35: COO.NO26.016 | T35: Modernização | U35: Modernização | V35: NGHI.0099 | W35: NGHI.0099 | AC35: 4500073938 | AD35: 7839949.5 | AE35: Reparo em 3 transformadores elevadores da UHE Tucuruí. | AF35: HITACHI ENERGY BRASIL LTDA | AG35: Revitalização dos transforamadores atualmente em operação na UHE Tucuruí | AH35: UHE Tucuruí | AI35: 0 | AK35: 0 | AM35: 0 | AN35: 1000000 | AO35: 0 | AP35: 1000000 | AQ35: 0 | AR35: 1000000 | AS35: 0 | AT35: 0 | AU35: =SUM(Tabela10[[#This Row],[jan/26]:[dez/26]]) -> 3000000 | AV35: 7500000 | AW35: 5000000 | AX35: 0 | AY35: 0 | AZ35: =SUM(Tabela10[[#This Row],[2026]:[2030]]) -> 15500000 | BA35: 0 | BB35: 0 | BC35: 0 | BD35: 0 | BE35: 0 | BF35: =SUM(Tabela10[[#This Row],[2026-2030]:[2035]]) -> 15500000 | BG35: {=_xlfn.SEQUENCE(COUNTA(Tabela10[Empresa]),1,1)} -> #VALUE! | BH35: COO.NO26.016 | BI35: =VLOOKUP(Tabela10[[#This Row],[ID real2]],[2]CONSOLIDADA!$AU:$AZ,6,FALSE) -> #N/A | BJ35: AGMGNO | BK35: 2025 | BL35: ENOR.00100 | BM35: COO0662 | BN35: COO.NO26.016 | BO35: Contratado | BP35: Nova Demanda | BQ35: Contratado | BR35: 5000000 | BS35: Reduzido em 2026 | BT35: COO.NO26.016 | BU35: Frederico Rodolfo Parente Doerner | BV35: =Tabela10[[#This Row],[Descrição do projeto]] -> Revitalização de transformador para a UHE Tucurui
A36: 353 | B36: {=AND(ISTEXT('Consolidado-Eletronorte'!#REF!),SUM('Consolidado-Eletronorte'!#REF!)>0)} -> #REF! | C36: =$J$13 -> Capex Orcamentário_PE2026_2030_red_35_porcentoR3_consulta.xlsx | D36: =$H$13 -> COO | E36: =$H$14 -> Lucas Martins | F36: =_xlfn.CONCAT(Tabela10[[#This Row],[VP]],Tabela10[[#This Row],[Analise Estrategia]]) -> COO353 | G36: =_xlfn.CONCAT('Consolidado-Eletronorte'!#REF!,"_",ROW('Consolidado-Eletronorte'!#REF!)-ROW('Consolidado-Eletronorte'!$G$18)) -> #REF! | H36: Corporativo | I36: Eletronorte | J36: Geração | K36: Modernização | L36: Modernização | M36: NGHI.0077 | P36: 13592/2022 | Q36: COO.NO26.009 | R36: Modernização do pórtico tomada d'água da UHE Tucuruí | S36: COO.NO26.009 | T36: Modernização | U36: Modernização | V36: NGHI.0077 | W36: NGHI.0077 | AC36: 4500082946 | AD36: 15130000 | AE36: Aquisição e montagem de pórtico para tomada d’água da CF1 e vertedouro. | AF36: BARDELLA SA INDUSTRIAS MECANICAS EM | AG36: AQUISICAO DE PORTICO PARA TOMADA D'AGUA PARA A CASA DE FORCA | AH36: UHE Tucuruí | AI36: 0 | AJ36: 0 | AK36: 0 | AL36: 3500000 | AM36: 0 | AN36: 0 | AO36: 0 | AP36: 3500000 | AQ36: 0 | AR36: 3000000 | AS36: 0 | AT36: 0 | AU36: =SUM(Tabela10[[#This Row],[jan/26]:[dez/26]]) -> 10000000 | AV36: 0 | AW36: 0 | AX36: 0 | AY36: 0 | AZ36: =SUM(Tabela10[[#This Row],[2026]:[2030]]) -> 10000000 | BA36: 0 | BB36: 0 | BC36: 0 | BD36: 0 | BE36: 0 | BF36: =SUM(Tabela10[[#This Row],[2026-2030]:[2035]]) -> 10000000 | BG36: {=_xlfn.SEQUENCE(COUNTA(Tabela10[Empresa]),1,1)} -> #VALUE! | BH36: COO.NO26.009 | BI36: =VLOOKUP(Tabela10[[#This Row],[ID real2]],[2]CONSOLIDADA!$AU:$AZ,6,FALSE) -> #N/A | BJ36: AGMGNO | BK36: 2025 | BL36: ENOR.00111.001 | BM36: COO0599 | BN36: COO.NO26.009 | BO36: Contratado | BP36: (PE) Não Requisitado e com ID Financeira | BQ36: Reajuste | BR36: 7865000 | BS36: Ajustado conforme contrato | BT36: COO.NO26.009 | BU36: Frederico Rodolfo Parente Doerner | BV36: =Tabela10[[#This Row],[Descrição do projeto]] -> Modernização do pórtico tomada d'água da UHE Tucuruí
B37: {=AND(ISTEXT('Consolidado-Eletronorte'!$H37:$M37),SUM('Consolidado-Eletronorte'!$AI37:$BF37)>0)} -> FALSE | C37: =$J$13 -> Capex Orcamentário_PE2026_2030_red_35_porcentoR3_consulta.xlsx | D37: =$H$13 -> COO | E37: =$H$14 -> Lucas Martins | G37: =_xlfn.CONCAT('Consolidado-Eletronorte'!$D37,"_",ROW('Consolidado-Eletronorte'!$G37)-ROW('Consolidado-Eletronorte'!$G$18)) -> COO_19 | Q37: COO.NO26.016 | R37: Revitalização de transformador para a UHE Tucurui | S37: COO.NO26.016 | V37: NGHI.0099 | W37: NGHI.0099 | AC37: 4500078421 | AD37: 4553427.2 | AE37: Substituição técnica de trafos 500/69 kV no pátio da UHE Tucuruí. | AF37: MEGATRANZ TRANSPORTES | AU37: =SUM(Tabela10[[#This Row],[jan/26]:[dez/26]]) -> 0 | AZ37: =SUM(Tabela10[[#This Row],[2026]:[2030]]) -> 0 | BF37: =SUM(Tabela10[[#This Row],[2026-2030]:[2035]]) -> 0 | BG37: {=_xlfn.SEQUENCE(COUNTA(Tabela10[Empresa]),1,1)} -> #VALUE! | BI37: =VLOOKUP(Tabela10[[#This Row],[ID real2]],[2]CONSOLIDADA!$AU:$AZ,6,FALSE) -> #N/A | BV37: =Tabela10[[#This Row],[Descrição do projeto]] -> Revitalização de transformador para a UHE Tucurui
A38: 280 | B38: {=AND(ISTEXT('Consolidado-Eletronorte'!#REF!),SUM('Consolidado-Eletronorte'!#REF!)>0)} -> #REF! | C38: =$J$13 -> Capex Orcamentário_PE2026_2030_red_35_porcentoR3_consulta.xlsx | D38: =$H$13 -> COO | E38: =$H$14 -> Lucas Martins | F38: =_xlfn.CONCAT(Tabela10[[#This Row],[VP]],Tabela10[[#This Row],[Analise Estrategia]]) -> COO280 | G38: =_xlfn.CONCAT('Consolidado-Eletronorte'!#REF!,"_",ROW('Consolidado-Eletronorte'!#REF!)-ROW('Consolidado-Eletronorte'!$G$18)) -> #REF! | H38: Corporativo | I38: Eletronorte | J38: Geração | K38: Modernização | L38: Modernização | M38: NGHI.0143 | P38: 13592/2022 | Q38: COO.NO26.019 | R38: Modernização dos Stop Logs da UHE Tucuruí | S38: COO.NO26.019 | T38: Modernização | U38: Modernização | V38: NGHI.0143 | W38: NGHI.0143 | AC38: 4500073892 | AD38: 10734567 | AE38: Revitalização dos stop logs das Casas de Força 01 e 02 da UHE Tucuruí. | AF38: OPEMACS SERVICOS TECNICOS LTDA | AG38: Contratação de Serviço de Revitalização dos Stop Logs das Casas de Força 01 e 02 da UHE Tucuruí. | AH38: UHE Tucuruí | AK38: 745051 | AN38: 745051 | AQ38: 745051 | AS38: 745051 | AU38: =SUM(Tabela10[[#This Row],[jan/26]:[dez/26]]) -> 2980204 | AV38: 4000000 | AW38: 2000000 | AX38: 0 | AY38: 0 | AZ38: =SUM(Tabela10[[#This Row],[2026]:[2030]]) -> 8980204 | BA38: 0 | BB38: 0 | BC38: 0 | BD38: 0 | BE38: 0 | BF38: =SUM(Tabela10[[#This Row],[2026-2030]:[2035]]) -> 8980204 | BG38: {=_xlfn.SEQUENCE(COUNTA(Tabela10[Empresa]),1,1)} -> #VALUE! | BH38: COO.NO26.019 | BI38: =VLOOKUP(Tabela10[[#This Row],[ID real2]],[2]CONSOLIDADA!$AU:$AZ,6,FALSE) -> #N/A | BJ38: OOGTM.N | BK38: 2025 | BL38: ENOR.00027.001 | BM38: COO0628 | BN38: COO.NO26.019 | BO38: Contratado | BP38: (PE) Não Requisitado e com ID Financeira | BQ38: RC não emitida | BR38: 4980204 | BS38: RD 2026 e 2mi para 20278 | BT38: COO.NO26.019 | BU38: Gilton Carlos De Andrade Furtado | BV38: =Tabela10[[#This Row],[Descrição do projeto]] -> Modernização dos Stop Logs da UHE Tucuruí
A39: 342 | B39: {=AND(ISTEXT('Consolidado-Eletronorte'!#REF!),SUM('Consolidado-Eletronorte'!#REF!)>0)} -> #REF! | C39: =$J$13 -> Capex Orcamentário_PE2026_2030_red_35_porcentoR3_consulta.xlsx | D39: =$H$13 -> COO | E39: =$H$14 -> Lucas Martins | F39: =_xlfn.CONCAT(Tabela10[[#This Row],[VP]],Tabela10[[#This Row],[Analise Estrategia]]) -> COO342 | G39: =_xlfn.CONCAT('Consolidado-Eletronorte'!#REF!,"_",ROW('Consolidado-Eletronorte'!#REF!)-ROW('Consolidado-Eletronorte'!$G$18)) -> #REF! | H39: Corporativo | I39: Eletronorte | J39: Geração | K39: Modernização | L39: Modernização | M39: NGHI.0143 | P39: 0484/2016 | Q39: COO.NO26.059 | R39: Revitalização do Vertedouro da UHCN | S39: COO.NO26.059 | T39: Modernização | U39: Modernização | V39: NGHI.0143 | W39: NGHI.0143 | Y39: Não emitido | AG39: COMPORTA VERTEDOURO VT-01,02,03,04,05,06,07,08, 09,10 | AH39: UHE Coaracy Nunes | AI39: 0 | AJ39: 0 | AK39: 0 | AL39: 0 | AM39: 0 | AN39: 0 | AP39: 0 | AR39: 0 | AS39: 0 | AU39: =SUM(Tabela10[[#This Row],[jan/26]:[dez/26]]) -> 0 | AV39: 7500000 | AW39: 7500000 | AX39: 0 | AY39: 0 | AZ39: =SUM(Tabela10[[#This Row],[2026]:[2030]]) -> 15000000 | BA39: 0 | BB39: 0 | BC39: 0 | BD39: 0 | BE39: 0 | BF39: =SUM(Tabela10[[#This Row],[2026-2030]:[2035]]) -> 15000000 | BG39: {=_xlfn.SEQUENCE(COUNTA(Tabela10[Empresa]),1,1)} -> #VALUE! | BH39: COO.NO26.059 | BI39: =VLOOKUP(Tabela10[[#This Row],[ID real2]],[2]CONSOLIDADA!$AU:$AZ,6,FALSE) -> #N/A | BJ39: OOGCN.N | BK39: 2026 | BL39: ENOR.00094 | BM39: 0 | BN39: COO.NO26.059 | BO39: Não iniciado | BP39: Nova Demanda | BQ39: RC não emitida | BR39: 3000000 | BS39: RD 2027-2028 | BT39: COO.NO26.059 | BU39: Naim Damasceno Campos | BV39: =Tabela10[[#This Row],[Descrição do projeto]] -> Revitalização do Vertedouro da UHCN
